<?xml version="1.0" encoding="utf-8"?>
<!-- This URDF was automatically created by SolidWorks to URDF Exporter! Originally created by Stephen Brawner (brawner@gmail.com) 
     Commit Version: 1.6.0-4-g7f85cfe  Build Version: 1.6.7995.38578
     For more information, please see http://wiki.ros.org/sw_urdf_exporter -->
<robot
  name="collectorarmv3">
  <link
    name="base_link">
    <!--
    <inertial>
      <origin
        xyz="-0.000431751513288531 1.47834302831424E-05 -0.0406498757569591"
        rpy="0 0 0" />
      <mass
        value="10.9600819085783" />
      <inertia
        ixx="0.0945695618080456"
        ixy="0.00119518049528138"
        ixz="0.000290680556593048"
        iyy="0.129434724287074"
        iyz="-9.9532969963045E-06"
        izz="0.193324726520427" />
    </inertial>
    -->
    <visual>
      <origin
        xyz="0 0 0"
        rpy="0 0 0" />
      <geometry>
        <mesh
          filename="package://collectorarmv3/meshes/base_link.STL" />
      </geometry>
      <material
        name="">
        <color
          rgba="1 1 1 1" />
      </material>
    </visual>
    <collision>
      <origin
        xyz="0 0 0"
        rpy="0 0 0" />
      <geometry>
        <mesh
          filename="package://collectorarmv3/meshes/base_link.STL" />
      </geometry>
    </collision>
  </link>
  <link
    name="arm_base">
    <inertial>
      <origin
        xyz="7.28396846272968E-19 1.76315571011505E-18 0.0360865793498005"
        rpy="0 0 0" />
      <mass
        value="0.665047517627195" />
      <inertia
        ixx="0.000801321710505508"
        ixy="0"
        ixz="-2.16841730089413E-20"
        iyy="0.0007819945070614"
        iyz="-2.57456921563231E-20"
        izz="0.000931687532031113" />
    </inertial>
    <visual>
      <origin
        xyz="0 0 0"
        rpy="0 0 0" />
      <geometry>
        <mesh
          filename="package://collectorarmv3/meshes/arm_base.STL" />
      </geometry>
      <material
        name="">
        <color
          rgba="1 1 1 1" />
      </material>
    </visual>
    <collision>
      <origin
        xyz="0 0 0"
        rpy="0 0 0" />
      <geometry>
        <mesh
          filename="package://collectorarmv3/meshes/arm_base.STL" />
      </geometry>
    </collision>
  </link>
  <joint
    name="arm_base"
    type="revolute">
    <origin
      xyz="0.110235143232275 -0.00377443959836907 0"
      rpy="0 0.00109387680445442 3.11540863358964" />
    <parent
      link="base_link" />
    <child
      link="arm_base" />
    <axis
      xyz="0 0 1" />
    <limit
      lower="-2.09"
      upper="2.09"
      effort="1.96"
      velocity="2.09" />
  </joint>
  <link
    name="joint1">
    <inertial>
      <origin
        xyz="7.18517713712401E-19 -0.0527192038585681 3.30821804044542E-17"
        rpy="0 0 0" />
      <mass
        value="0.121429178051326" />
      <inertia
        ixx="0.000117162142598077"
        ixy="-6.19418892543942E-21"
        ixz="-5.9292306307801E-21"
        iyy="4.0582127817409E-05"
        iyz="1.0142839467032E-20"
        izz="8.93455922872464E-05" />
    </inertial>
    <visual>
      <origin
        xyz="0 0 0"
        rpy="0 0 0" />
      <geometry>
        <mesh
          filename="package://collectorarmv3/meshes/joint1.STL" />
      </geometry>
      <material
        name="">
        <color
          rgba="1 1 1 1" />
      </material>
    </visual>
    <collision>
      <origin
        xyz="0 0 0"
        rpy="0 0 0" />
      <geometry>
        <mesh
          filename="package://collectorarmv3/meshes/joint1.STL" />
      </geometry>
    </collision>
  </link>
  <joint
    name="joint1"
    type="revolute">
    <origin
      xyz="0 0 0.0735"
      rpy="-1.5708 0 -1.5708" />
    <parent
      link="arm_base" />
    <child
      link="joint1" />
    <axis
      xyz="0 0 -1" />
    <limit
      lower="-1.4"
      upper="1.4"
      effort="1.96"
      velocity="2.09" />
  </joint>
  <link
    name="joint2">
    <inertial>
      <origin
        xyz="-0.000367263012555461 0.04643145539527 -9.64656529610046E-18"
        rpy="0 0 0" />
      <mass
        value="0.131283140376496" />
      <inertia
        ixx="0.000146877503943008"
        ixy="8.00219059863326E-07"
        ixz="-5.29395592033938E-21"
        iyy="4.57156398302099E-05"
        iyz="3.10489047985684E-20"
        izz="0.000115415073146959" />
    </inertial>
    <visual>
      <origin
        xyz="0 0 0"
        rpy="0 0 0" />
      <geometry>
        <mesh
          filename="package://collectorarmv3/meshes/joint2.STL" />
      </geometry>
      <material
        name="">
        <color
          rgba="1 1 1 1" />
      </material>
    </visual>
    <collision>
      <origin
        xyz="0 0 0"
        rpy="0 0 0" />
      <geometry>
        <mesh
          filename="package://collectorarmv3/meshes/joint2.STL" />
      </geometry>
    </collision>
  </link>
  <joint
    name="joint2"
    type="revolute">
    <origin
      xyz="0 -0.1045 0"
      rpy="0 0 -3.1416" />
    <parent
      link="joint1" />
    <child
      link="joint2" />
    <axis
      xyz="0 0 1" />
    <limit
      lower="-2.09"
      upper="2.09"
      effort="1.96"
      velocity="2.09" />
  </joint>
  <link
    name="joint3">
    <inertial>
      <origin
        xyz="0.01039197803158 0.0307503516421674 -5.23805174582059E-18"
        rpy="0 0 0" />
      <mass
        value="0.219866762368024" />
      <inertia
        ixx="0.000172745723837527"
        ixy="2.03545346580773E-06"
        ixz="2.03287907341032E-20"
        iyy="0.000115202012236034"
        iyz="1.88630991746248E-21"
        izz="0.000159888587287607" />
    </inertial>
    <visual>
      <origin
        xyz="0 0 0"
        rpy="0 0 0" />
      <geometry>
        <mesh
          filename="package://collectorarmv3/meshes/joint3.STL" />
      </geometry>
      <material
        name="">
        <color
          rgba="1 1 1 1" />
      </material>
    </visual>
    <collision>
      <origin
        xyz="0 0 0"
        rpy="0 0 0" />
      <geometry>
        <mesh
          filename="package://collectorarmv3/meshes/joint3.STL" />
      </geometry>
    </collision>
  </link>
  <joint
    name="joint3"
    type="revolute">
    <origin
      xyz="-0.000783044610374008 0.0989969031896361 0"
      rpy="0 0 0" />
    <parent
      link="joint2" />
    <child
      link="joint3" />
    <axis
      xyz="0 0 1" />
    <limit
      lower="-2.09"
      upper="2.09"
      effort="1.96"
      velocity="2.09" />
  </joint>
  <link
    name="joint4">
    <inertial>
      <origin
        xyz="-0.000277596496871631 -0.0281145016215643 -0.037041068420988"
        rpy="0 0 0" />
      <mass
        value="0.0877692802125948" />
      <inertia
        ixx="6.5935291174991E-05"
        ixy="5.20638114340617E-07"
        ixz="5.88851187244421E-07"
        iyy="8.01839237432345E-05"
        iyz="-1.16396143968237E-05"
        izz="4.38010425722549E-05" />
    </inertial>
    <visual>
      <origin
        xyz="0 0 0"
        rpy="0 0 0" />
      <geometry>
        <mesh
          filename="package://collectorarmv3/meshes/joint4.STL" />
      </geometry>
      <material
        name="">
        <color
          rgba="1 1 1 1" />
      </material>
    </visual>
    <collision>
      <origin
        xyz="0 0 0"
        rpy="0 0 0" />
      <geometry>
        <mesh
          filename="package://collectorarmv3/meshes/joint4.STL" />
      </geometry>
    </collision>
  </link>
  <joint
    name="joint4"
    type="revolute">
    <origin
      xyz="0.0210000000000001 0.0739722155183903 0"
      rpy="-1.57079632679501 -1.56966466905772 -3.14159265358968" />
    <parent
      link="joint3" />
    <child
      link="joint4" />
    <axis
      xyz="0 0 -1" />
    <limit
      lower="-2.09"
      upper="2.09"
      effort="1.96"
      velocity="2.09" />
  </joint>
  <link
    name="joint5">
    <inertial>
      <origin
        xyz="0.0107453852867667 -0.0401379763855603 -4.33680868994202E-18"
        rpy="0 0 0" />
      <mass
        value="0.106491203259952" />
      <inertia
        ixx="7.00067496887713E-05"
        ixy="1.26099042598824E-05"
        ixz="5.0821976835258E-21"
        iyy="6.88640890322061E-05"
        iyz="-9.42324153820409E-21"
        izz="5.43700689342052E-05" />
    </inertial>
    <visual>
      <origin
        xyz="0 0 0"
        rpy="0 0 0" />
      <geometry>
        <mesh
          filename="package://collectorarmv3/meshes/joint5.STL" />
      </geometry>
      <material
        name="">
        <color
          rgba="1 1 1 1" />
      </material>
    </visual>
    <collision>
      <origin
        xyz="0 0 0"
        rpy="0 0 0" />
      <geometry>
        <mesh
          filename="package://collectorarmv3/meshes/joint5.STL" />
      </geometry>
    </collision>
  </link>
  <joint
    name="joint5"
    type="revolute">
    <origin
      xyz="-0.00150000000000001 0 -0.00858728860074032"
      rpy="1.5707963267949 0.717783208856171 -1.5707963267949" />
    <parent
      link="joint4" />
    <child
      link="joint5" />
    <axis
      xyz="0 0 -1" />
    <limit
      lower="-0.1"
      upper="2.09"
      effort="1.96"
      velocity="2.09" />
  </joint>
</robot>